Workbook

Sheet README
A1: Pipeline and Presence: CRM and marketing-intelligence model
A2: SIMULATED data for a fictional professional-services firm in Nairobi. No real client, firm or staff data is used.
A4: Purpose | B4: Reconstructs the dashboards, data-quality checks and follow-ups that a Clients and Markets support associate would run from Salesforce, with every number a live formula.
A5: Read first | B5: Dashboard_LoS and DQ_Scorecard. Then Priority_Accounts, Dashboard_Industry, Owner_Hygiene, Feedback and Events.
A6: Inputs | B6: Inputs sheet: as-of date, stale threshold, FY27 dates, stage probabilities and simulated targets. Change them and every sheet updates.
A7: Data | B7: Opps, Accounts, Activities and Owners are the simulated Salesforce export. Opps columns O onward are formula flags.
A8: Followups | B8: Static list generated by analysis/audit.py for owner chasing.
A9: Checks | B9: The workbook is reconciled to an independent Python audit.
A10: Colour code | B10: Blue = input or raw data. Black = formula. Green = link to another sheet. Yellow fill = key output.
A11: Tags | B11: [E] = computed in Python (normalised name key, feedback theme tags).

Sheet Dashboard_LoS
A1: Line of Service dashboard (KES millions)
A2: Reconstructs the monthly BD-meeting dashboard: pipeline, FY27 coverage, win rate, cycle time and data quality. Targets are simulated.
A4: Line of service | B4: Open opps | C4: Open pipeline (KES m) | D4: Weighted pipeline (KES m) | E4: FY27-closing weighted (KES m) | F4: FY27 target (KES m) | G4: Won FY27 YTD (KES m) | H4: Remaining to target (KES m) | I4: Coverage (x) | J4: Closed, look-back | K4: Won, look-back | L4: Win rate | M4: Avg cycle, won (days) | N4: Open opps data-clean
A5: =Inputs!A20 -> Assurance | B5: =COUNTIFS(Opps!$D$5:$D$954,A5,Opps!$O$5:$O$954,1) -> 84 | C5: =SUMIFS(Opps!$F$5:$F$954,Opps!$D$5:$D$954,A5,Opps!$O$5:$O$954,1)/1000000 -> 1065.947 | D5: =SUMIFS(Opps!$S$5:$S$954,Opps!$D$5:$D$954,A5,Opps!$O$5:$O$954,1)/1000000 -> 351.31025 | E5: =SUMIFS(Opps!$S$5:$S$954,Opps!$D$5:$D$954,A5,Opps!$AE$5:$AE$954,1)/1000000 -> 347.75445 | F5: =Inputs!B20 -> 1100 | G5: =SUMIFS(Opps!$F$5:$F$954,Opps!$D$5:$D$954,A5,Opps!$AF$5:$AF$954,1)/1000000 -> 124.263 | H5: =MAX(F5-G5,0) -> 975.737 | I5: =IF(H5=0,"",E5/H5) -> 0.35640183 | J5: =COUNTIFS(Opps!$D$5:$D$954,A5,Opps!$AG$5:$AG$954,1) -> 122 | K5: =COUNTIFS(Opps!$D$5:$D$954,A5,Opps!$AG$5:$AG$954,1,Opps!$E$5:$E$954,"Closed Won") -> 40 | L5: =IF(J5=0,"",K5/J5) -> 0.32786885 | M5: =AVERAGEIFS(Opps!$AH$5:$AH$954,Opps!$D$5:$D$954,A5,Opps!$E$5:$E$954,"Closed Won") -> 165.275 | N5: =COUNTIFS(Opps!$D$5:$D$954,A5,Opps!$O$5:$O$954,1,Opps!$AD$5:$AD$954,1)/B5 -> 0.47619048
A6: =Inputs!A21 -> Tax & Legal | B6: =COUNTIFS(Opps!$D$5:$D$954,A6,Opps!$O$5:$O$954,1) -> 101 | C6: =SUMIFS(Opps!$F$5:$F$954,Opps!$D$5:$D$954,A6,Opps!$O$5:$O$954,1)/1000000 -> 942.23 | D6: =SUMIFS(Opps!$S$5:$S$954,Opps!$D$5:$D$954,A6,Opps!$O$5:$O$954,1)/1000000 -> 318.80875 | E6: =SUMIFS(Opps!$S$5:$S$954,Opps!$D$5:$D$954,A6,Opps!$AE$5:$AE$954,1)/1000000 -> 309.4824 | F6: =Inputs!B21 -> 1500 | G6: =SUMIFS(Opps!$F$5:$F$954,Opps!$D$5:$D$954,A6,Opps!$AF$5:$AF$954,1)/1000000 -> 286.747 | H6: =MAX(F6-G6,0) -> 1213.253 | I6: =IF(H6=0,"",E6/H6) -> 0.2550848 | J6: =COUNTIFS(Opps!$D$5:$D$954,A6,Opps!$AG$5:$AG$954,1) -> 167 | K6: =COUNTIFS(Opps!$D$5:$D$954,A6,Opps!$AG$5:$AG$954,1,Opps!$E$5:$E$954,"Closed Won") -> 61 | L6: =IF(J6=0,"",K6/J6) -> 0.36526946 | M6: =AVERAGEIFS(Opps!$AH$5:$AH$954,Opps!$D$5:$D$954,A6,Opps!$E$5:$E$954,"Closed Won") -> 164.44262 | N6: =COUNTIFS(Opps!$D$5:$D$954,A6,Opps!$O$5:$O$954,1,Opps!$AD$5:$AD$954,1)/B6 -> 0.48514851
A7: =Inputs!A22 -> Deals | B7: =COUNTIFS(Opps!$D$5:$D$954,A7,Opps!$O$5:$O$954,1) -> 63 | C7: =SUMIFS(Opps!$F$5:$F$954,Opps!$D$5:$D$954,A7,Opps!$O$5:$O$954,1)/1000000 -> 1979.643 | D7: =SUMIFS(Opps!$S$5:$S$954,Opps!$D$5:$D$954,A7,Opps!$O$5:$O$954,1)/1000000 -> 924.6952 | E7: =SUMIFS(Opps!$S$5:$S$954,Opps!$D$5:$D$954,A7,Opps!$AE$5:$AE$954,1)/1000000 -> 924.6952 | F7: =Inputs!B22 -> 900 | G7: =SUMIFS(Opps!$F$5:$F$954,Opps!$D$5:$D$954,A7,Opps!$AF$5:$AF$954,1)/1000000 -> 726.163 | H7: =MAX(F7-G7,0) -> 173.837 | I7: =IF(H7=0,"",E7/H7) -> 5.3193233 | J7: =COUNTIFS(Opps!$D$5:$D$954,A7,Opps!$AG$5:$AG$954,1) -> 81 | K7: =COUNTIFS(Opps!$D$5:$D$954,A7,Opps!$AG$5:$AG$954,1,Opps!$E$5:$E$954,"Closed Won") -> 38 | L7: =IF(J7=0,"",K7/J7) -> 0.4691358 | M7: =AVERAGEIFS(Opps!$AH$5:$AH$954,Opps!$D$5:$D$954,A7,Opps!$E$5:$E$954,"Closed Won") -> 145 | N7: =COUNTIFS(Opps!$D$5:$D$954,A7,Opps!$O$5:$O$954,1,Opps!$AD$5:$AD$954,1)/B7 -> 0.34920635
A8: =Inputs!A23 -> Consulting | B8: =COUNTIFS(Opps!$D$5:$D$954,A8,Opps!$O$5:$O$954,1) -> 95 | C8: =SUMIFS(Opps!$F$5:$F$954,Opps!$D$5:$D$954,A8,Opps!$O$5:$O$954,1)/1000000 -> 2486.486 | D8: =SUMIFS(Opps!$S$5:$S$954,Opps!$D$5:$D$954,A8,Opps!$O$5:$O$954,1)/1000000 -> 1025.7814 | E8: =SUMIFS(Opps!$S$5:$S$954,Opps!$D$5:$D$954,A8,Opps!$AE$5:$AE$954,1)/1000000 -> 1018.9516 | F8: =Inputs!B23 -> 1900 | G8: =SUMIFS(Opps!$F$5:$F$954,Opps!$D$5:$D$954,A8,Opps!$AF$5:$AF$954,1)/1000000 -> 576.565 | H8: =MAX(F8-G8,0) -> 1323.435 | I8: =IF(H8=0,"",E8/H8) -> 0.7699295 | J8: =COUNTIFS(Opps!$D$5:$D$954,A8,Opps!$AG$5:$AG$954,1) -> 152 | K8: =COUNTIFS(Opps!$D$5:$D$954,A8,Opps!$AG$5:$AG$954,1,Opps!$E$5:$E$954,"Closed Won") -> 53 | L8: =IF(J8=0,"",K8/J8) -> 0.34868421 | M8: =AVERAGEIFS(Opps!$AH$5:$AH$954,Opps!$D$5:$D$954,A8,Opps!$E$5:$E$954,"Closed Won") -> 159.66038 | N8: =COUNTIFS(Opps!$D$5:$D$954,A8,Opps!$O$5:$O$954,1,Opps!$AD$5:$AD$954,1)/B8 -> 0.43157895
A9: =Inputs!A24 -> Risk | B9: =COUNTIFS(Opps!$D$5:$D$954,A9,Opps!$O$5:$O$954,1) -> 30 | C9: =SUMIFS(Opps!$F$5:$F$954,Opps!$D$5:$D$954,A9,Opps!$O$5:$O$954,1)/1000000 -> 341.496 | D9: =SUMIFS(Opps!$S$5:$S$954,Opps!$D$5:$D$954,A9,Opps!$O$5:$O$954,1)/1000000 -> 97.7875 | E9: =SUMIFS(Opps!$S$5:$S$954,Opps!$D$5:$D$954,A9,Opps!$AE$5:$AE$954,1)/1000000 -> 97.7875 | F9: =Inputs!B24 -> 600 | G9: =SUMIFS(Opps!$F$5:$F$954,Opps!$D$5:$D$954,A9,Opps!$AF$5:$AF$954,1)/1000000 -> 186.987 | H9: =MAX(F9-G9,0) -> 413.013 | I9: =IF(H9=0,"",E9/H9) -> 0.23676616 | J9: =COUNTIFS(Opps!$D$5:$D$954,A9,Opps!$AG$5:$AG$954,1) -> 55 | K9: =COUNTIFS(Opps!$D$5:$D$954,A9,Opps!$AG$5:$AG$954,1,Opps!$E$5:$E$954,"Closed Won") -> 24 | L9: =IF(J9=0,"",K9/J9) -> 0.43636364 | M9: =AVERAGEIFS(Opps!$AH$5:$AH$954,Opps!$D$5:$D$954,A9,Opps!$E$5:$E$954,"Closed Won") -> 147.5 | N9: =COUNTIFS(Opps!$D$5:$D$954,A9,Opps!$O$5:$O$954,1,Opps!$AD$5:$AD$954,1)/B9 -> 0.53333333
A10: Total | B10: =SUM(B5:B9) -> 373 | C10: =SUM(C5:C9) -> 6815.802 | D10: =SUM(D5:D9) -> 2718.3831 | E10: =SUM(E5:E9) -> 2698.6712 | F10: =SUM(F5:F9) -> 6000 | G10: =SUM(G5:G9) -> 1900.725 | H10: =SUM(H5:H9) -> 4099.275 | I10: =E10/H10 -> 0.6583289 | J10: =SUM(J5:J9) -> 577 | K10: =SUM(K5:K9) -> 216 | L10: =K10/J10 -> 0.37435009 | M10: =AVERAGEIFS(Opps!$AH$5:$AH$954,Opps!$E$5:$E$954,"Closed Won") -> 158.12037 | N10: =COUNTIFS(Opps!$O$5:$O$954,1,Opps!$AD$5:$AD$954,1)/B10 -> 0.45040214
A12: Coverage = weighted pipeline expected to close in FY27 / (target - won year to date). Below 1.0x means the weighted pipeline alone cannot reach the target.

Sheet Dashboard_Industry
A1: Industry group dashboard (KES millions)
A2: Industry comes from the account record; accounts without an industry fall into 'Unassigned' until fixed.
A4: Industry | B4: Open opps | C4: Open pipeline (KES m) | D4: Weighted pipeline (KES m) | E4: Share of weighted | F4: Closed, look-back | G4: Won, look-back | H4: Win rate | I4: Open opps data-clean
A5: Agribusiness | B5: =COUNTIFS(Opps!$P$5:$P$954,A5,Opps!$O$5:$O$954,1) -> 38 | C5: =SUMIFS(Opps!$F$5:$F$954,Opps!$P$5:$P$954,A5,Opps!$O$5:$O$954,1)/1000000 -> 671.024 | D5: =SUMIFS(Opps!$S$5:$S$954,Opps!$P$5:$P$954,A5,Opps!$O$5:$O$954,1)/1000000 -> 318.40885 | E5: =D5/D$14 -> 0.11713171 | F5: =COUNTIFS(Opps!$P$5:$P$954,A5,Opps!$AG$5:$AG$954,1) -> 50 | G5: =COUNTIFS(Opps!$P$5:$P$954,A5,Opps!$AG$5:$AG$954,1,Opps!$E$5:$E$954,"Closed Won") -> 16 | H5: =IF(F5=0,"",G5/F5) -> 0.32 | I5: =IF(B5=0,"",COUNTIFS(Opps!$P$5:$P$954,A5,Opps!$O$5:$O$954,1,Opps!$AD$5:$AD$954,1)/B5) -> 0.42105263
A6: Consumer & Retail | B6: =COUNTIFS(Opps!$P$5:$P$954,A6,Opps!$O$5:$O$954,1) -> 45 | C6: =SUMIFS(Opps!$F$5:$F$954,Opps!$P$5:$P$954,A6,Opps!$O$5:$O$954,1)/1000000 -> 741.69 | D6: =SUMIFS(Opps!$S$5:$S$954,Opps!$P$5:$P$954,A6,Opps!$O$5:$O$954,1)/1000000 -> 265.83615 | E6: =D6/D$14 -> 0.097792011 | F6: =COUNTIFS(Opps!$P$5:$P$954,A6,Opps!$AG$5:$AG$954,1) -> 63 | G6: =COUNTIFS(Opps!$P$5:$P$954,A6,Opps!$AG$5:$AG$954,1,Opps!$E$5:$E$954,"Closed Won") -> 18 | H6: =IF(F6=0,"",G6/F6) -> 0.28571429 | I6: =IF(B6=0,"",COUNTIFS(Opps!$P$5:$P$954,A6,Opps!$O$5:$O$954,1,Opps!$AD$5:$AD$954,1)/B6) -> 0.42222222
A7: Energy & Resources | B7: =COUNTIFS(Opps!$P$5:$P$954,A7,Opps!$O$5:$O$954,1) -> 44 | C7: =SUMIFS(Opps!$F$5:$F$954,Opps!$P$5:$P$954,A7,Opps!$O$5:$O$954,1)/1000000 -> 936.058 | D7: =SUMIFS(Opps!$S$5:$S$954,Opps!$P$5:$P$954,A7,Opps!$O$5:$O$954,1)/1000000 -> 394.9023 | E7: =D7/D$14 -> 0.14527103 | F7: =COUNTIFS(Opps!$P$5:$P$954,A7,Opps!$AG$5:$AG$954,1) -> 56 | G7: =COUNTIFS(Opps!$P$5:$P$954,A7,Opps!$AG$5:$AG$954,1,Opps!$E$5:$E$954,"Closed Won") -> 31 | H7: =IF(F7=0,"",G7/F7) -> 0.55357143 | I7: =IF(B7=0,"",COUNTIFS(Opps!$P$5:$P$954,A7,Opps!$O$5:$O$954,1,Opps!$AD$5:$AD$954,1)/B7) -> 0.52272727
A8: Financial Services | B8: =COUNTIFS(Opps!$P$5:$P$954,A8,Opps!$O$5:$O$954,1) -> 99 | C8: =SUMIFS(Opps!$F$5:$F$954,Opps!$P$5:$P$954,A8,Opps!$O$5:$O$954,1)/1000000 -> 1758.697 | D8: =SUMIFS(Opps!$S$5:$S$954,Opps!$P$5:$P$954,A8,Opps!$O$5:$O$954,1)/1000000 -> 603.7617 | E8: =D8/D$14 -> 0.22210324 | F8: =COUNTIFS(Opps!$P$5:$P$954,A8,Opps!$AG$5:$AG$954,1) -> 157 | G8: =COUNTIFS(Opps!$P$5:$P$954,A8,Opps!$AG$5:$AG$954,1,Opps!$E$5:$E$954,"Closed Won") -> 59 | H8: =IF(F8=0,"",G8/F8) -> 0.37579618 | I8: =IF(B8=0,"",COUNTIFS(Opps!$P$5:$P$954,A8,Opps!$O$5:$O$954,1,Opps!$AD$5:$AD$954,1)/B8) -> 0.52525253
A9: Health | B9: =COUNTIFS(Opps!$P$5:$P$954,A9,Opps!$O$5:$O$954,1) -> 13 | C9: =SUMIFS(Opps!$F$5:$F$954,Opps!$P$5:$P$954,A9,Opps!$O$5:$O$954,1)/1000000 -> 160.42 | D9: =SUMIFS(Opps!$S$5:$S$954,Opps!$P$5:$P$954,A9,Opps!$O$5:$O$954,1)/1000000 -> 64.63045 | E9: =D9/D$14 -> 0.023775328 | F9: =COUNTIFS(Opps!$P$5:$P$954,A9,Opps!$AG$5:$AG$954,1) -> 28 | G9: =COUNTIFS(Opps!$P$5:$P$954,A9,Opps!$AG$5:$AG$954,1,Opps!$E$5:$E$954,"Closed Won") -> 16 | H9: =IF(F9=0,"",G9/F9) -> 0.57142857 | I9: =IF(B9=0,"",COUNTIFS(Opps!$P$5:$P$954,A9,Opps!$O$5:$O$954,1,Opps!$AD$5:$AD$954,1)/B9) -> 0.46153846
A10: Public Sector & Development | B10: =COUNTIFS(Opps!$P$5:$P$954,A10,Opps!$O$5:$O$954,1) -> 47 | C10: =SUMIFS(Opps!$F$5:$F$954,Opps!$P$5:$P$954,A10,Opps!$O$5:$O$954,1)/1000000 -> 587.049 | D10: =SUMIFS(Opps!$S$5:$S$954,Opps!$P$5:$P$954,A10,Opps!$O$5:$O$954,1)/1000000 -> 220.68835 | E10: =D10/D$14 -> 0.081183682 | F10: =COUNTIFS(Opps!$P$5:$P$954,A10,Opps!$AG$5:$AG$954,1) -> 73 | G10: =COUNTIFS(Opps!$P$5:$P$954,A10,Opps!$AG$5:$AG$954,1,Opps!$E$5:$E$954,"Closed Won") -> 28 | H10: =IF(F10=0,"",G10/F10) -> 0.38356164 | I10: =IF(B10=0,"",COUNTIFS(Opps!$P$5:$P$954,A10,Opps!$O$5:$O$954,1,Opps!$AD$5:$AD$954,1)/B10) -> 0.36170213
A11: Real Estate & Infrastructure | B11: =COUNTIFS(Opps!$P$5:$P$954,A11,Opps!$O$5:$O$954,1) -> 19 | C11: =SUMIFS(Opps!$F$5:$F$954,Opps!$P$5:$P$954,A11,Opps!$O$5:$O$954,1)/1000000 -> 536.621 | D11: =SUMIFS(Opps!$S$5:$S$954,Opps!$P$5:$P$954,A11,Opps!$O$5:$O$954,1)/1000000 -> 311.1257 | E11: =D11/D$14 -> 0.11445248 | F11: =COUNTIFS(Opps!$P$5:$P$954,A11,Opps!$AG$5:$AG$954,1) -> 21 | G11: =COUNTIFS(Opps!$P$5:$P$954,A11,Opps!$AG$5:$AG$954,1,Opps!$E$5:$E$954,"Closed Won") -> 6 | H11: =IF(F11=0,"",G11/F11) -> 0.28571429 | I11: =IF(B11=0,"",COUNTIFS(Opps!$P$5:$P$954,A11,Opps!$O$5:$O$954,1,Opps!$AD$5:$AD$954,1)/B11) -> 0.36842105
A12: Technology, Media & Telecom | B12: =COUNTIFS(Opps!$P$5:$P$954,A12,Opps!$O$5:$O$954,1) -> 56 | C12: =SUMIFS(Opps!$F$5:$F$954,Opps!$P$5:$P$954,A12,Opps!$O$5:$O$954,1)/1000000 -> 1187.057 | D12: =SUMIFS(Opps!$S$5:$S$954,Opps!$P$5:$P$954,A12,Opps!$O$5:$O$954,1)/1000000 -> 443.7796 | E12: =D12/D$14 -> 0.16325131 | F12: =COUNTIFS(Opps!$P$5:$P$954,A12,Opps!$AG$5:$AG$954,1) -> 100 | G12: =COUNTIFS(Opps!$P$5:$P$954,A12,Opps!$AG$5:$AG$954,1,Opps!$E$5:$E$954,"Closed Won") -> 37 | H12: =IF(F12=0,"",G12/F12) -> 0.37 | I12: =IF(B12=0,"",COUNTIFS(Opps!$P$5:$P$954,A12,Opps!$O$5:$O$954,1,Opps!$AD$5:$AD$954,1)/B12) -> 0.42857143
A13: Unassigned | B13: =COUNTIFS(Opps!$P$5:$P$954,A13,Opps!$O$5:$O$954,1) -> 12 | C13: =SUMIFS(Opps!$F$5:$F$954,Opps!$P$5:$P$954,A13,Opps!$O$5:$O$954,1)/1000000 -> 237.186 | D13: =SUMIFS(Opps!$S$5:$S$954,Opps!$P$5:$P$954,A13,Opps!$O$5:$O$954,1)/1000000 -> 95.25 | E13: =D13/D$14 -> 0.035039211 | F13: =COUNTIFS(Opps!$P$5:$P$954,A13,Opps!$AG$5:$AG$954,1) -> 29 | G13: =COUNTIFS(Opps!$P$5:$P$954,A13,Opps!$AG$5:$AG$954,1,Opps!$E$5:$E$954,"Closed Won") -> 5 | H13: =IF(F13=0,"",G13/F13) -> 0.17241379 | I13: =IF(B13=0,"",COUNTIFS(Opps!$P$5:$P$954,A13,Opps!$O$5:$O$954,1,Opps!$AD$5:$AD$954,1)/B13) -> 0.33333333
A14: Total | B14: =SUM(B5:B13) -> 373 | C14: =SUM(C5:C13) -> 6815.802 | D14: =SUM(D5:D13) -> 2718.3831 | E14: =SUM(E5:E13) -> 1 | F14: =SUM(F5:F13) -> 577 | G14: =SUM(G5:G13) -> 216 | H14: =G14/F14 -> 0.37435009

Sheet Priority_Accounts
A1: Priority accounts: pipeline and recency of contact
A2: Priority list is an input. Open opportunities and last touch are live formulas.
A4: Account ID | B4: Account | C4: Industry | D4: Driver | E4: Open opps | F4: Weighted pipeline (KES m) | G4: Last touchpoint | H4: Days since touch | I4: Needs attention?
A5: A0001 | B5: =INDEX(Accounts!$B$5:$B$336,MATCH(A5,Accounts!$A$5:$A$336,0)) -> Jambo Microfinance Limited | C5: =INDEX(Accounts!$K$5:$K$336,MATCH(A5,Accounts!$A$5:$A$336,0)) -> Financial Services | D5: =INDEX(Owners!$B$5:$B$32,MATCH(INDEX(Accounts!$G$5:$G$336,MATCH(A5,Accounts!$A$5:$A$336,0)),Owners!$A$5:$A$32,0)) -> Amina Otieno | E5: =COUNTIFS(Opps!$B$5:$B$954,A5,Opps!$O$5:$O$954,1) -> 4 | F5: =SUMIFS(Opps!$S$5:$S$954,Opps!$B$5:$B$954,A5,Opps!$O$5:$O$954,1)/1000000 -> 68.29475 | G5: =IF(COUNTIFS(Activities!$B$5:$B$1453,A5)=0,"",_xlfn.MAXIFS(Activities!$D$5:$D$1453,Activities!$B$5:$B$1453,A5)) -> 46259 | H5: =IF(G5="","",Inputs!$B$4-G5) -> 55 | I5: =IF(OR(E5=0,H5="",H5>90),"Yes","")
A6: A0002 | B6: =INDEX(Accounts!$B$5:$B$336,MATCH(A6,Accounts!$A$5:$A$336,0)) -> Umoja Capital Limited | C6: =INDEX(Accounts!$K$5:$K$336,MATCH(A6,Accounts!$A$5:$A$336,0)) -> Financial Services | D6: =INDEX(Owners!$B$5:$B$32,MATCH(INDEX(Accounts!$G$5:$G$336,MATCH(A6,Accounts!$A$5:$A$336,0)),Owners!$A$5:$A$32,0)) -> Brian Chebet | E6: =COUNTIFS(Opps!$B$5:$B$954,A6,Opps!$O$5:$O$954,1) -> 2 | F6: =SUMIFS(Opps!$S$5:$S$954,Opps!$B$5:$B$954,A6,Opps!$O$5:$O$954,1)/1000000 -> 7.272 | G6: =IF(COUNTIFS(Activities!$B$5:$B$1453,A6)=0,"",_xlfn.MAXIFS(Activities!$D$5:$D$1453,Activities!$B$5:$B$1453,A6)) -> 46245 | H6: =IF(G6="","",Inputs!$B$4-G6) -> 69 | I6: =IF(OR(E6=0,H6="",H6>90),"Yes","")
A7: A0003 | B7: =INDEX(Accounts!$B$5:$B$336,MATCH(A7,Accounts!$A$5:$A$336,0)) -> Nile Microfinance Limited | C7: =INDEX(Accounts!$K$5:$K$336,MATCH(A7,Accounts!$A$5:$A$336,0)) -> Financial Services | D7: =INDEX(Owners!$B$5:$B$32,MATCH(INDEX(Accounts!$G$5:$G$336,MATCH(A7,Accounts!$A$5:$A$336,0)),Owners!$A$5:$A$32,0)) -> Cynthia Odhiambo | E7: =COUNTIFS(Opps!$B$5:$B$954,A7,Opps!$O$5:$O$954,1) -> 4 | F7: =SUMIFS(Opps!$S$5:$S$954,Opps!$B$5:$B$954,A7,Opps!$O$5:$O$954,1)/1000000 -> 12.8949 | G7: =IF(COUNTIFS(Activities!$B$5:$B$1453,A7)=0,"",_xlfn.MAXIFS(Activities!$D$5:$D$1453,Activities!$B$5:$B$1453,A7)) -> 46261 | H7: =IF(G7="","",Inputs!$B$4-G7) -> 53 | I7: =IF(OR(E7=0,H7="",H7>90),"Yes","")
A8: A0004 | B8: =INDEX(Accounts!$B$5:$B$336,MATCH(A8,Accounts!$A$5:$A$336,0)) -> Pwani Asset Managers Limited | C8: =INDEX(Accounts!$K$5:$K$336,MATCH(A8,Accounts!$A$5:$A$336,0)) -> Financial Services | D8: =INDEX(Owners!$B$5:$B$32,MATCH(INDEX(Accounts!$G$5:$G$336,MATCH(A8,Accounts!$A$5:$A$336,0)),Owners!$A$5:$A$32,0)) -> Daniel Wanjiru | E8: =COUNTIFS(Opps!$B$5:$B$954,A8,Opps!$O$5:$O$954,1) -> 4 | F8: =SUMIFS(Opps!$S$5:$S$954,Opps!$B$5:$B$954,A8,Opps!$O$5:$O$954,1)/1000000 -> 11.1043 | G8: =IF(COUNTIFS(Activities!$B$5:$B$1453,A8)=0,"",_xlfn.MAXIFS(Activities!$D$5:$D$1453,Activities!$B$5:$B$1453,A8)) -> 46292 | H8: =IF(G8="","",Inputs!$B$4-G8) -> 22 | I8: =IF(OR(E8=0,H8="",H8>90),"Yes","")
A9: A0005 | B9: =INDEX(Accounts!$B$5:$B$336,MATCH(A9,Accounts!$A$5:$A$336,0)) -> Twiga Agri Limited | C9: =INDEX(Accounts!$K$5:$K$336,MATCH(A9,Accounts!$A$5:$A$336,0)) -> Agribusiness | D9: =INDEX(Owners!$B$5:$B$32,MATCH(INDEX(Accounts!$G$5:$G$336,MATCH(A9,Accounts!$A$5:$A$336,0)),Owners!$A$5:$A$32,0)) -> Esther Kiprop | E9: =COUNTIFS(Opps!$B$5:$B$954,A9,Opps!$O$5:$O$954,1) -> 5 | F9: =SUMIFS(Opps!$S$5:$S$954,Opps!$B$5:$B$954,A9,Opps!$O$5:$O$954,1)/1000000 -> 8.21025 | G9: =IF(COUNTIFS(Activities!$B$5:$B$1453,A9)=0,"",_xlfn.MAXIFS(Activities!$D$5:$D$1453,Activities!$B$5:$B$1453,A9)) -> 46313 | H9: =IF(G9="","",Inputs!$B$4-G9) -> 1 | I9: =IF(OR(E9=0,H9="",H9>90),"Yes","")
A10: A0006 | B10: =INDEX(Accounts!$B$5:$B$336,MATCH(A10,Accounts!$A$5:$A$336,0)) -> Kibo Microfinance Limited | C10: =INDEX(Accounts!$K$5:$K$336,MATCH(A10,Accounts!$A$5:$A$336,0)) -> Financial Services | D10: =INDEX(Owners!$B$5:$B$32,MATCH(INDEX(Accounts!$G$5:$G$336,MATCH(A10,Accounts!$A$5:$A$336,0)),Owners!$A$5:$A$32,0)) -> Felix Barasa | E10: =COUNTIFS(Opps!$B$5:$B$954,A10,Opps!$O$5:$O$954,1) -> 2 | F10: =SUMIFS(Opps!$S$5:$S$954,Opps!$B$5:$B$954,A10,Opps!$O$5:$O$954,1)/1000000 -> 22.3261 | G10: =IF(COUNTIFS(Activities!$B$5:$B$1453,A10)=0,"",_xlfn.MAXIFS(Activities!$D$5:$D$1453,Activities!$B$5:$B$1453,A10)) -> 46286 | H10: =IF(G10="","",Inputs!$B$4-G10) -> 28 | I10: =IF(OR(E10=0,H10="",H10>90),"Yes","")
A11: A0007 | B11: =INDEX(Accounts!$B$5:$B$336,MATCH(A11,Accounts!$A$5:$A$336,0)) -> Nile County Government | C11: =INDEX(Accounts!$K$5:$K$336,MATCH(A11,Accounts!$A$5:$A$336,0)) -> Public Sector & Development | D11: =INDEX(Owners!$B$5:$B$32,MATCH(INDEX(Accounts!$G$5:$G$336,MATCH(A11,Accounts!$A$5:$A$336,0)),Owners!$A$5:$A$32,0)) -> Grace Mwangi | E11: =COUNTIFS(Opps!$B$5:$B$954,A11,Opps!$O$5:$O$954,1) -> 4 | F11: =SUMIFS(Opps!$S$5:$S$954,Opps!$B$5:$B$954,A11,Opps!$O$5:$O$954,1)/1000000 -> 10.19965 | G11: =IF(COUNTIFS(Activities!$B$5:$B$1453,A11)=0,"",_xlfn.MAXIFS(Activities!$D$5:$D$1453,Activities!$B$5:$B$1453,A11)) -> 46234 | H11: =IF(G11="","",Inputs!$B$4-G11) -> 80 | I11: =IF(OR(E11=0,H11="",H11>90),"Yes","")
A12: A0008 | B12: =INDEX(Accounts!$B$5:$B$336,MATCH(A12,Accounts!$A$5:$A$336,0)) -> Tembo Capital Limited | C12: =INDEX(Accounts!$K$5:$K$336,MATCH(A12,Accounts!$A$5:$A$336,0)) -> Financial Services | D12: =INDEX(Owners!$B$5:$B$32,MATCH(INDEX(Accounts!$G$5:$G$336,MATCH(A12,Accounts!$A$5:$A$336,0)),Owners!$A$5:$A$32,0)) -> Amina Otieno | E12: =COUNTIFS(Opps!$B$5:$B$954,A12,Opps!$O$5:$O$954,1) -> 5 | F12: =SUMIFS(Opps!$S$5:$S$954,Opps!$B$5:$B$954,A12,Opps!$O$5:$O$954,1)/1000000 -> 10.6029 | G12: =IF(COUNTIFS(Activities!$B$5:$B$1453,A12)=0,"",_xlfn.MAXIFS(Activities!$D$5:$D$1453,Activities!$B$5:$B$1453,A12)) -> 46293 | H12: =IF(G12="","",Inputs!$B$4-G12) -> 21 | I12: =IF(OR(E12=0,H12="",H12>90),"Yes","")
A13: A0009 | B13: =INDEX(Accounts!$B$5:$B$336,MATCH(A13,Accounts!$A$5:$A$336,0)) -> Rift Cloud Limited | C13: =INDEX(Accounts!$K$5:$K$336,MATCH(A13,Accounts!$A$5:$A$336,0)) -> Technology, Media & Telecom | D13: =INDEX(Owners!$B$5:$B$32,MATCH(INDEX(Accounts!$G$5:$G$336,MATCH(A13,Accounts!$A$5:$A$336,0)),Owners!$A$5:$A$32,0)) -> Brian Chebet | E13: =COUNTIFS(Opps!$B$5:$B$954,A13,Opps!$O$5:$O$954,1) -> 2 | F13: =SUMIFS(Opps!$S$5:$S$954,Opps!$B$5:$B$954,A13,Opps!$O$5:$O$954,1)/1000000 -> 4.27325 | G13: =IF(COUNTIFS(Activities!$B$5:$B$1453,A13)=0,"",_xlfn.MAXIFS(Activities!$D$5:$D$1453,Activities!$B$5:$B$1453,A13)) -> 46306 | H13: =IF(G13="","",Inputs!$B$4-G13) -> 8 | I13: =IF(OR(E13=0,H13="",H13>90),"Yes","")
A14: A0010 | B14: =INDEX(Accounts!$B$5:$B$336,MATCH(A14,Accounts!$A$5:$A$336,0)) -> Umoja Asset Managers Limited | C14: =INDEX(Accounts!$K$5:$K$336,MATCH(A14,Accounts!$A$5:$A$336,0)) -> Financial Services | D14: =INDEX(Owners!$B$5:$B$32,MATCH(INDEX(Accounts!$G$5:$G$336,MATCH(A14,Accounts!$A$5:$A$336,0)),Owners!$A$5:$A$32,0)) -> Cynthia Odhiambo | E14: =COUNTIFS(Opps!$B$5:$B$954,A14,Opps!$O$5:$O$954,1) -> 4 | F14: =SUMIFS(Opps!$S$5:$S$954,Opps!$B$5:$B$954,A14,Opps!$O$5:$O$954,1)/1000000 -> 77.5095 | G14: =IF(COUNTIFS(Activities!$B$5:$B$1453,A14)=0,"",_xlfn.MAXIFS(Activities!$D$5:$D$1453,Activities!$B$5:$B$1453,A14)) -> 46262 | H14: =IF(G14="","",Inputs!$B$4-G14) -> 52 | I14: =IF(OR(E14=0,H14="",H14>90),"Yes","")
A15: A0011 | B15: =INDEX(Accounts!$B$5:$B$336,MATCH(A15,Accounts!$A$5:$A$336,0)) -> Rift Capital Limited | C15: =INDEX(Accounts!$K$5:$K$336,MATCH(A15,Accounts!$A$5:$A$336,0)) -> Financial Services | D15: =INDEX(Owners!$B$5:$B$32,MATCH(INDEX(Accounts!$G$5:$G$336,MATCH(A15,Accounts!$A$5:$A$336,0)),Owners!$A$5:$A$32,0)) -> Daniel Wanjiru | E15: =COUNTIFS(Opps!$B$5:$B$954,A15,Opps!$O$5:$O$954,1) -> 5 | F15: =SUMIFS(Opps!$S$5:$S$954,Opps!$B$5:$B$954,A15,Opps!$O$5:$O$954,1)/1000000 -> 20.50555 | G15: =IF(COUNTIFS(Activities!$B$5:$B$1453,A15)=0,"",_xlfn.MAXIFS(Activities!$D$5:$D$1453,Activities!$B$5:$B$1453,A15)) -> 46307 | H15: =IF(G15="","",Inputs!$B$4-G15) -> 7 | I15: =IF(OR(E15=0,H15="",H15>90),"Yes","")
A16: A0012 | B16: =INDEX(Accounts!$B$5:$B$336,MATCH(A16,Accounts!$A$5:$A$336,0)) -> Safari Microfinance Limited | C16: =INDEX(Accounts!$K$5:$K$336,MATCH(A16,Accounts!$A$5:$A$336,0)) -> Financial Services | D16: =INDEX(Owners!$B$5:$B$32,MATCH(INDEX(Accounts!$G$5:$G$336,MATCH(A16,Accounts!$A$5:$A$336,0)),Owners!$A$5:$A$32,0)) -> Esther Kiprop | E16: =COUNTIFS(Opps!$B$5:$B$954,A16,Opps!$O$5:$O$954,1) -> 5 | F16: =SUMIFS(Opps!$S$5:$S$954,Opps!$B$5:$B$954,A16,Opps!$O$5:$O$954,1)/1000000 -> 13.684 | G16: =IF(COUNTIFS(Activities!$B$5:$B$1453,A16)=0,"",_xlfn.MAXIFS(Activities!$D$5:$D$1453,Activities!$B$5:$B$1453,A16)) -> 46261 | H16: =IF(G16="","",Inputs!$B$4-G16) -> 53 | I16: =IF(OR(E16=0,H16="",H16>90),"Yes","")
... A44: A0040 | B44: =INDEX(Accounts!$B$5:$B$336,MATCH(A44,Accounts!$A$5:$A$336,0)) -> Amani Insurance Limited | C44: =INDEX(Accounts!$K$5:$K$336,MATCH(A44,Accounts!$A$5:$A$336,0)) -> Financial Services | D44: =INDEX(Owners!$B$5:$B$32,MATCH(INDEX(Accounts!$G$5:$G$336,MATCH(A44,Accounts!$A$5:$A$336,0)),Owners!$A$5:$A$32,0)) -> Esther Kiprop | E44: =COUNTIFS(Opps!$B$5:$B$954,A44,Opps!$O$5:$O$954,1) -> 2 | F44: =SUMIFS(Opps!$S$5:$S$954,Opps!$B$5:$B$954,A44,Opps!$O$5:$O$954,1)/1000000 -> 16.7685 | G44: =IF(COUNTIFS(Activities!$B$5:$B$1453,A44)=0,"",_xlfn.MAXIFS(Activities!$D$5:$D$1453,Activities!$B$5:$B$1453,A44)) -> 46312 | H44: =IF(G44="","",Inputs!$B$4-G44) -> 2 | I44: =IF(OR(E44=0,H44="",H44>90),"Yes","")
A46: Priority accounts | E46: =COUNTA(A5:A44) -> 40
A47: With at least one open opportunity | E47: =COUNTIF(E5:E44,">0") -> 38
A48: Touched in the last 90 days | E48: =COUNTIFS(H5:H44,"<=90") -> 37
A49: Needing attention (no open opp, or no touch in 90 days) | E49: =COUNTIF(I5:I44,"Yes") -> 5

Sheet DQ_Scorecard
A1: Salesforce data-quality scorecard
A2: Eight opportunity rules and two account rules. Open-opportunity clean rate is the headline measure.
A4: Rule | B4: Applies to | C4: Failing | D4: Population | E4: Failure rate | F4: What the owner should do
A5: Amount missing or zero | B5: all opportunities | C5: =SUM(Opps!$U$5:$U$954) -> 66 | D5: =COUNTA(Opps!$A$5:$A$954) -> 950 | E5: =C5/D5 -> 0.069473684 | F5: Add an estimated amount
A6: No owner assigned | B6: all opportunities | C6: =SUM(Opps!$V$5:$V$954) -> 27 | D6: =COUNTA(Opps!$A$5:$A$954) -> 950 | E6: =C6/D6 -> 0.028421053 | F6: Assign an owner
A7: Owner has left or is inactive | B7: open | C7: =SUM(Opps!$W$5:$W$954) -> 40 | D7: =SUM(Opps!$O$5:$O$954) -> 373 | E7: =C7/D7 -> 0.10723861 | F7: Reassign the opportunity
A8: Open with close date in the past | B8: open | C8: =SUM(Opps!$X$5:$X$954) -> 56 | D8: =SUM(Opps!$O$5:$O$954) -> 373 | E8: =C8/D8 -> 0.15013405 | F8: Update the close date or close it
A9: No activity for more than the stale threshold | B9: open | C9: =SUM(Opps!$Y$5:$Y$954) -> 82 | D9: =SUM(Opps!$O$5:$O$954) -> 373 | E9: =C9/D9 -> 0.21983914 | F9: Log an activity or confirm status
A10: Probability does not match stage | B10: open | C10: =SUM(Opps!$Z$5:$Z$954) -> 22 | D10: =SUM(Opps!$O$5:$O$954) -> 373 | E10: =C10/D10 -> 0.058981233 | F10: Correct the probability
A11: No next step recorded | B11: open | C11: =SUM(Opps!$AA$5:$AA$954) -> 29 | D11: =SUM(Opps!$O$5:$O$954) -> 373 | E11: =C11/D11 -> 0.077747989 | F11: Record the next step
A12: Lost without a reason | B12: closed lost | C12: =SUM(Opps!$AB$5:$AB$954) -> 64 | D12: =COUNTIFS(Opps!$E$5:$E$954,"Closed Lost") -> 361 | E12: =C12/D12 -> 0.17728532 | F12: Add the lost reason
A14: Account: missing industry | C14: =SUM(Accounts!$L$5:$L$336) -> 17 | D14: =COUNTA(Accounts!$A$5:$A$336) -> 332 | E14: =C14/D14 -> 0.051204819
A15: Account: part of a duplicate pair | C15: =SUM(Accounts!$I$5:$I$336) -> 24 | D15: =COUNTA(Accounts!$A$5:$A$336) -> 332 | E15: =C15/D15 -> 0.072289157
A17: Open opportunities with no data issue | C17: =COUNTIFS(Opps!$O$5:$O$954,1,Opps!$AD$5:$AD$954,1) -> 168 | D17: =SUM(Opps!$O$5:$O$954) -> 373 | E17: =C17/D17 -> 0.45040214
A18: Open opportunities with at least one issue | C18: =D17-C17 -> 205 | E18: =C18/D17 -> 0.54959786
A19: Issue count to chase (all rules, all opportunities) | C19: =SUM(Opps!$AC$5:$AC$954) -> 386

Sheet Owner_Hygiene
A1: Owner hygiene: who has opportunities to fix
A2: Use this to prepare the follow-up calls and the Salesforce clinics. Open opportunities only.
A4: Owner ID | B4: Name | C4: Grade | D4: Active? | E4: Open opps | F4: Opps with an issue | G4: Clean rate | H4: Issues to fix
A5: =Owners!A5 -> U001 | B5: =Owners!B5 -> Amina Otieno | C5: =Owners!C5 -> Partner | D5: =Owners!E5 -> Yes | E5: =COUNTIFS(Opps!$K$5:$K$954,A5,Opps!$O$5:$O$954,1) -> 23 | F5: =COUNTIFS(Opps!$K$5:$K$954,A5,Opps!$O$5:$O$954,1,Opps!$AD$5:$AD$954,0) -> 10 | G5: =IF(E5=0,"",1-F5/E5) -> 0.56521739 | H5: =SUMIFS(Opps!$AC$5:$AC$954,Opps!$K$5:$K$954,A5,Opps!$O$5:$O$954,1) -> 13
A6: =Owners!A6 -> U002 | B6: =Owners!B6 -> Brian Chebet | C6: =Owners!C6 -> Partner | D6: =Owners!E6 -> Yes | E6: =COUNTIFS(Opps!$K$5:$K$954,A6,Opps!$O$5:$O$954,1) -> 14 | F6: =COUNTIFS(Opps!$K$5:$K$954,A6,Opps!$O$5:$O$954,1,Opps!$AD$5:$AD$954,0) -> 7 | G6: =IF(E6=0,"",1-F6/E6) -> 0.5 | H6: =SUMIFS(Opps!$AC$5:$AC$954,Opps!$K$5:$K$954,A6,Opps!$O$5:$O$954,1) -> 8
A7: =Owners!A7 -> U003 | B7: =Owners!B7 -> Cynthia Odhiambo | C7: =Owners!C7 -> Partner | D7: =Owners!E7 -> Yes | E7: =COUNTIFS(Opps!$K$5:$K$954,A7,Opps!$O$5:$O$954,1) -> 22 | F7: =COUNTIFS(Opps!$K$5:$K$954,A7,Opps!$O$5:$O$954,1,Opps!$AD$5:$AD$954,0) -> 8 | G7: =IF(E7=0,"",1-F7/E7) -> 0.63636364 | H7: =SUMIFS(Opps!$AC$5:$AC$954,Opps!$K$5:$K$954,A7,Opps!$O$5:$O$954,1) -> 8
A8: =Owners!A8 -> U004 | B8: =Owners!B8 -> Daniel Wanjiru | C8: =Owners!C8 -> Partner | D8: =Owners!E8 -> Yes | E8: =COUNTIFS(Opps!$K$5:$K$954,A8,Opps!$O$5:$O$954,1) -> 21 | F8: =COUNTIFS(Opps!$K$5:$K$954,A8,Opps!$O$5:$O$954,1,Opps!$AD$5:$AD$954,0) -> 10 | G8: =IF(E8=0,"",1-F8/E8) -> 0.52380952 | H8: =SUMIFS(Opps!$AC$5:$AC$954,Opps!$K$5:$K$954,A8,Opps!$O$5:$O$954,1) -> 11
A9: =Owners!A9 -> U005 | B9: =Owners!B9 -> Esther Kiprop | C9: =Owners!C9 -> Partner | D9: =Owners!E9 -> Yes | E9: =COUNTIFS(Opps!$K$5:$K$954,A9,Opps!$O$5:$O$954,1) -> 21 | F9: =COUNTIFS(Opps!$K$5:$K$954,A9,Opps!$O$5:$O$954,1,Opps!$AD$5:$AD$954,0) -> 11 | G9: =IF(E9=0,"",1-F9/E9) -> 0.47619048 | H9: =SUMIFS(Opps!$AC$5:$AC$954,Opps!$K$5:$K$954,A9,Opps!$O$5:$O$954,1) -> 12
A10: =Owners!A10 -> U006 | B10: =Owners!B10 -> Felix Barasa | C10: =Owners!C10 -> Partner | D10: =Owners!E10 -> Yes | E10: =COUNTIFS(Opps!$K$5:$K$954,A10,Opps!$O$5:$O$954,1) -> 16 | F10: =COUNTIFS(Opps!$K$5:$K$954,A10,Opps!$O$5:$O$954,1,Opps!$AD$5:$AD$954,0) -> 9 | G10: =IF(E10=0,"",1-F10/E10) -> 0.4375 | H10: =SUMIFS(Opps!$AC$5:$AC$954,Opps!$K$5:$K$954,A10,Opps!$O$5:$O$954,1) -> 13
A11: =Owners!A11 -> U007 | B11: =Owners!B11 -> Grace Mwangi | C11: =Owners!C11 -> Partner | D11: =Owners!E11 -> Yes | E11: =COUNTIFS(Opps!$K$5:$K$954,A11,Opps!$O$5:$O$954,1) -> 16 | F11: =COUNTIFS(Opps!$K$5:$K$954,A11,Opps!$O$5:$O$954,1,Opps!$AD$5:$AD$954,0) -> 10 | G11: =IF(E11=0,"",1-F11/E11) -> 0.375 | H11: =SUMIFS(Opps!$AC$5:$AC$954,Opps!$K$5:$K$954,A11,Opps!$O$5:$O$954,1) -> 14
A12: =Owners!A12 -> U008 | B12: =Owners!B12 -> Hassan Mutua | C12: =Owners!C12 -> Director | D12: =Owners!E12 -> Yes | E12: =COUNTIFS(Opps!$K$5:$K$954,A12,Opps!$O$5:$O$954,1) -> 13 | F12: =COUNTIFS(Opps!$K$5:$K$954,A12,Opps!$O$5:$O$954,1,Opps!$AD$5:$AD$954,0) -> 2 | G12: =IF(E12=0,"",1-F12/E12) -> 0.84615385 | H12: =SUMIFS(Opps!$AC$5:$AC$954,Opps!$K$5:$K$954,A12,Opps!$O$5:$O$954,1) -> 4
A13: =Owners!A13 -> U009 | B13: =Owners!B13 -> Irene Nyambura | C13: =Owners!C13 -> Director | D13: =Owners!E13 -> Yes | E13: =COUNTIFS(Opps!$K$5:$K$954,A13,Opps!$O$5:$O$954,1) -> 11 | F13: =COUNTIFS(Opps!$K$5:$K$954,A13,Opps!$O$5:$O$954,1,Opps!$AD$5:$AD$954,0) -> 4 | G13: =IF(E13=0,"",1-F13/E13) -> 0.63636364 | H13: =SUMIFS(Opps!$AC$5:$AC$954,Opps!$K$5:$K$954,A13,Opps!$O$5:$O$954,1) -> 8
A14: =Owners!A14 -> U010 | B14: =Owners!B14 -> James Kamau | C14: =Owners!C14 -> Director | D14: =Owners!E14 -> Yes | E14: =COUNTIFS(Opps!$K$5:$K$954,A14,Opps!$O$5:$O$954,1) -> 9 | F14: =COUNTIFS(Opps!$K$5:$K$954,A14,Opps!$O$5:$O$954,1,Opps!$AD$5:$AD$954,0) -> 6 | G14: =IF(E14=0,"",1-F14/E14) -> 0.33333333 | H14: =SUMIFS(Opps!$AC$5:$AC$954,Opps!$K$5:$K$954,A14,Opps!$O$5:$O$954,1) -> 8
A15: =Owners!A15 -> U011 | B15: =Owners!B15 -> Kevin Ochieng | C15: =Owners!C15 -> Director | D15: =Owners!E15 -> Yes | E15: =COUNTIFS(Opps!$K$5:$K$954,A15,Opps!$O$5:$O$954,1) -> 9 | F15: =COUNTIFS(Opps!$K$5:$K$954,A15,Opps!$O$5:$O$954,1,Opps!$AD$5:$AD$954,0) -> 6 | G15: =IF(E15=0,"",1-F15/E15) -> 0.33333333 | H15: =SUMIFS(Opps!$AC$5:$AC$954,Opps!$K$5:$K$954,A15,Opps!$O$5:$O$954,1) -> 7
A16: =Owners!A16 -> U012 | B16: =Owners!B16 -> Lucy Kariuki | C16: =Owners!C16 -> Director | D16: =Owners!E16 -> No | E16: =COUNTIFS(Opps!$K$5:$K$954,A16,Opps!$O$5:$O$954,1) -> 24 | F16: =COUNTIFS(Opps!$K$5:$K$954,A16,Opps!$O$5:$O$954,1,Opps!$AD$5:$AD$954,0) -> 24 | G16: =IF(E16=0,"",1-F16/E16) -> 0 | H16: =SUMIFS(Opps!$AC$5:$AC$954,Opps!$K$5:$K$954,A16,Opps!$O$5:$O$954,1) -> 32
... A32: =Owners!A32 -> U028 | B32: =Owners!B32 -> Faith Mutua | C32: =Owners!C32 -> Senior Manager | D32: =Owners!E32 -> Yes | E32: =COUNTIFS(Opps!$K$5:$K$954,A32,Opps!$O$5:$O$954,1) -> 9 | F32: =COUNTIFS(Opps!$K$5:$K$954,A32,Opps!$O$5:$O$954,1,Opps!$AD$5:$AD$954,0) -> 2 | G32: =IF(E32=0,"",1-F32/E32) -> 0.77777778 | H32: =SUMIFS(Opps!$AC$5:$AC$954,Opps!$K$5:$K$954,A32,Opps!$O$5:$O$954,1) -> 2
B33: (no owner) | E33: =COUNTIFS(Opps!$K$5:$K$954,"",Opps!$O$5:$O$954,1) -> 10 | F33: =COUNTIFS(Opps!$K$5:$K$954,"",Opps!$O$5:$O$954,1,Opps!$AD$5:$AD$954,0) -> 10 | H33: =SUMIFS(Opps!$AC$5:$AC$954,Opps!$K$5:$K$954,"",Opps!$O$5:$O$954,1) -> 20
B34: Total | E34: =SUM(E5:E33) -> 373 | F34: =SUM(F5:F33) -> 205 | H34: =SUM(H5:H33) -> 271

Sheet Feedback
A1: Client feedback consolidation (simulated survey)
A2: Theme tags come from keyword matching in Python [E]. Summary tables are live formulas.
A4: Feedback ID | B4: Account ID | C4: Line of service | D4: Survey date | E4: Rating (1-5) | F4: Comment | G4: Follow-up status | H4: Theme [E] | I4: Sentiment | L4: Line of service | M4: Responses | N4: Average rating | O4: % positive | P4: % negative
A5: F0001 | B5: A0307 | C5: Deals | D5: 46287 | E5: 5 | F5: Quick to respond and always available when we need guidance. | G5: Closed | H5: responsiveness | I5: =IF(E5>=4,"Positive",IF(E5<=2,"Negative","Neutral")) -> Positive | L5: Assurance | M5: =COUNTIFS($C$5:$C$184,L5) -> 42 | N5: =AVERAGEIFS($E$5:$E$184,$C$5:$C$184,L5) -> 3.4047619 | O5: =COUNTIFS($C$5:$C$184,L5,$I$5:$I$184,"Positive")/M5 -> 0.47619048 | P5: =COUNTIFS($C$5:$C$184,L5,$I$5:$I$184,"Negative")/M5 -> 0.21428571
A6: F0002 | B6: A0294 | C6: Consulting | D6: 46281 | E6: 5 | F6: Quick to respond and always available when we need guidance. | G6: Responded | H6: responsiveness | I6: =IF(E6>=4,"Positive",IF(E6<=2,"Negative","Neutral")) -> Positive | L6: Tax & Legal | M6: =COUNTIFS($C$5:$C$184,L6) -> 42 | N6: =AVERAGEIFS($E$5:$E$184,$C$5:$C$184,L6) -> 3.6666667 | O6: =COUNTIFS($C$5:$C$184,L6,$I$5:$I$184,"Positive")/M6 -> 0.64285714 | P6: =COUNTIFS($C$5:$C$184,L6,$I$5:$I$184,"Negative")/M6 -> 0.16666667
A7: F0003 | B7: A0028 | C7: Assurance | D7: 46045 | E7: 5 | F7: The client portal made sharing documents simple. | G7: Closed | H7: digital | I7: =IF(E7>=4,"Positive",IF(E7<=2,"Negative","Neutral")) -> Positive | L7: Deals | M7: =COUNTIFS($C$5:$C$184,L7) -> 27 | N7: =AVERAGEIFS($E$5:$E$184,$C$5:$C$184,L7) -> 3.7407407 | O7: =COUNTIFS($C$5:$C$184,L7,$I$5:$I$184,"Positive")/M7 -> 0.66666667 | P7: =COUNTIFS($C$5:$C$184,L7,$I$5:$I$184,"Negative")/M7 -> 0.14814815
A8: F0004 | B8: A0037 | C8: Consulting | D8: 45995 | E8: 1 | F8: We were not told about changes to the timeline early enough. | G8: Closed | H8: communication | I8: =IF(E8>=4,"Positive",IF(E8<=2,"Negative","Neutral")) -> Negative | L8: Consulting | M8: =COUNTIFS($C$5:$C$184,L8) -> 52 | N8: =AVERAGEIFS($E$5:$E$184,$C$5:$C$184,L8) -> 3.8076923 | O8: =COUNTIFS($C$5:$C$184,L8,$I$5:$I$184,"Positive")/M8 -> 0.71153846 | P8: =COUNTIFS($C$5:$C$184,L8,$I$5:$I$184,"Negative")/M8 -> 0.17307692
A9: F0005 | B9: A0167 | C9: Deals | D9: 46306 | E9: 3 | F9: Updates were clear and regular. | G9: Responded | H9: communication | I9: =IF(E9>=4,"Positive",IF(E9<=2,"Negative","Neutral")) -> Neutral | L9: Risk | M9: =COUNTIFS($C$5:$C$184,L9) -> 17 | N9: =AVERAGEIFS($E$5:$E$184,$C$5:$C$184,L9) -> 3.4705882 | O9: =COUNTIFS($C$5:$C$184,L9,$I$5:$I$184,"Positive")/M9 -> 0.58823529 | P9: =COUNTIFS($C$5:$C$184,L9,$I$5:$I$184,"Negative")/M9 -> 0.29411765
A10: F0006 | B10: A0035 | C10: Tax & Legal | D10: 46164 | E10: 3 | F10: Advice felt generic and not tailored to our industry. | G10: Closed | H10: insight | I10: =IF(E10>=4,"Positive",IF(E10<=2,"Negative","Neutral")) -> Neutral
A11: F0007 | B11: A0108 | C11: Tax & Legal | D11: 46197 | E11: 5 | F11: The client portal made sharing documents simple. | G11: Closed | H11: digital | I11: =IF(E11>=4,"Positive",IF(E11<=2,"Negative","Neutral")) -> Positive | L11: All | M11: =COUNTA($A$5:$A$184) -> 180 | N11: =AVERAGE($E$5:$E$184) -> 3.6388889 | O11: =COUNTIF($I$5:$I$184,"Positive")/M11 -> 0.62222222 | P11: =COUNTIF($I$5:$I$184,"Negative")/M11 -> 0.18888889
A12: F0008 | B12: A0216 | C12: Consulting | D12: 46269 | E12: 5 | F12: Event invitations are relevant to our work. | G12: Open | H12: digital | I12: =IF(E12>=4,"Positive",IF(E12<=2,"Negative","Neutral")) -> Positive | L12: Net sentiment (points, % positive - % negative) | P12: =(O11-P11)*100 -> 43.333333
A13: F0009 | B13: A0229 | C13: Assurance | D13: 46091 | E13: 4 | F13: Updates were clear and regular. | G13: Open | H13: communication | I13: =IF(E13>=4,"Positive",IF(E13<=2,"Negative","Neutral")) -> Positive | L13: Open follow-ups | P13: =COUNTIF($G$5:$G$184,"Open") -> 50
A14: F0010 | B14: A0085 | C14: Assurance | D14: 46017 | E14: 2 | F14: Pricing was higher than we expected for the scope. | G14: Closed | H14: value | I14: =IF(E14>=4,"Positive",IF(E14<=2,"Negative","Neutral")) -> Negative
A15: F0011 | B15: A0014 | C15: Assurance | D15: 46016 | E15: 4 | F15: The team brought genuinely useful sector insight. | G15: Open | H15: insight | I15: =IF(E15>=4,"Positive",IF(E15<=2,"Negative","Neutral")) -> Positive
A16: F0012 | B16: A0164 | C16: Tax & Legal | D16: 46132 | E16: 2 | F16: Too many separate emails from different teams. | G16: Responded | H16: digital | I16: =IF(E16>=4,"Positive",IF(E16<=2,"Negative","Neutral")) -> Negative | L16: Theme | M16: Positive | N16: Neutral | O16: Negative | P16: Total
A17: F0013 | B17: A0297 | C17: Risk | D17: 46183 | E17: 4 | F17: Updates were clear and regular. | G17: Open | H17: communication | I17: =IF(E17>=4,"Positive",IF(E17<=2,"Negative","Neutral")) -> Positive | L17: responsiveness | M17: =COUNTIFS($H$5:$H$184,L17,$I$5:$I$184,"Positive") -> 18 | N17: =COUNTIFS($H$5:$H$184,L17,$I$5:$I$184,"Neutral") -> 3 | O17: =COUNTIFS($H$5:$H$184,L17,$I$5:$I$184,"Negative") -> 4 | P17: =SUM(M17:O17) -> 25
A18: F0014 | B18: A0295 | C18: Tax & Legal | D18: 46251 | E18: 2 | F18: Pricing was higher than we expected for the scope. | G18: Responded | H18: value | I18: =IF(E18>=4,"Positive",IF(E18<=2,"Negative","Neutral")) -> Negative | L18: insight | M18: =COUNTIFS($H$5:$H$184,L18,$I$5:$I$184,"Positive") -> 22 | N18: =COUNTIFS($H$5:$H$184,L18,$I$5:$I$184,"Neutral") -> 10 | O18: =COUNTIFS($H$5:$H$184,L18,$I$5:$I$184,"Negative") -> 5 | P18: =SUM(M18:O18) -> 37
A19: F0015 | B19: A0119 | C19: Tax & Legal | D19: 45987 | E19: 4 | F19: Event invitations are relevant to our work. | G19: Open | H19: digital | I19: =IF(E19>=4,"Positive",IF(E19<=2,"Negative","Neutral")) -> Positive | L19: value | M19: =COUNTIFS($H$5:$H$184,L19,$I$5:$I$184,"Positive") -> 24 | N19: =COUNTIFS($H$5:$H$184,L19,$I$5:$I$184,"Neutral") -> 4 | O19: =COUNTIFS($H$5:$H$184,L19,$I$5:$I$184,"Negative") -> 6 | P19: =SUM(M19:O19) -> 34
A20: F0016 | B20: A0297 | C20: Assurance | D20: 46056 | E20: 4 | F20: Fees were fair for the quality delivered. | G20: Responded | H20: value | I20: =IF(E20>=4,"Positive",IF(E20<=2,"Negative","Neutral")) -> Positive | L20: communication | M20: =COUNTIFS($H$5:$H$184,L20,$I$5:$I$184,"Positive") -> 23 | N20: =COUNTIFS($H$5:$H$184,L20,$I$5:$I$184,"Neutral") -> 11 | O20: =COUNTIFS($H$5:$H$184,L20,$I$5:$I$184,"Negative") -> 12 | P20: =SUM(M20:O20) -> 46
A21: F0017 | B21: A0130 | C21: Deals | D21: 46164 | E21: 5 | F21: The client portal made sharing documents simple. | G21: Responded | H21: digital | I21: =IF(E21>=4,"Positive",IF(E21<=2,"Negative","Neutral")) -> Positive | L21: digital | M21: =COUNTIFS($H$5:$H$184,L21,$I$5:$I$184,"Positive") -> 25 | N21: =COUNTIFS($H$5:$H$184,L21,$I$5:$I$184,"Neutral") -> 6 | O21: =COUNTIFS($H$5:$H$184,L21,$I$5:$I$184,"Negative") -> 7 | P21: =SUM(M21:O21) -> 38
A22: F0018 | B22: A0268 | C22: Assurance | D22: 46023 | E22: 2 | F22: Pricing was higher than we expected for the scope. | G22: Open | H22: value | I22: =IF(E22>=4,"Positive",IF(E22<=2,"Negative","Neutral")) -> Negative
A23: F0019 | B23: A0208 | C23: Tax & Legal | D23: 46042 | E23: 3 | F23: Quick to respond and always available when we need guidance. | G23: Responded | H23: responsiveness | I23: =IF(E23>=4,"Positive",IF(E23<=2,"Negative","Neutral")) -> Neutral
A24: F0020 | B24: A0092 | C24: Assurance | D24: 46146 | E24: 5 | F24: The client portal made sharing documents simple. | G24: Responded | H24: digital | I24: =IF(E24>=4,"Positive",IF(E24<=2,"Negative","Neutral")) -> Positive
A25: F0021 | B25: A0045 | C25: Tax & Legal | D25: 46164 | E25: 4 | F25: The team brought genuinely useful sector insight. | G25: Open | H25: insight | I25: =IF(E25>=4,"Positive",IF(E25<=2,"Negative","Neutral")) -> Positive
A26: F0022 | B26: A0220 | C26: Assurance | D26: 46246 | E26: 4 | F26: Clear scoping avoided surprises on cost. | G26: Open | H26: value | I26: =IF(E26>=4,"Positive",IF(E26<=2,"Negative","Neutral")) -> Positive
A27: F0023 | B27: A0277 | C27: Assurance | D27: 46296 | E27: 4 | F27: Event invitations are relevant to our work. | G27: Responded | H27: digital | I27: =IF(E27>=4,"Positive",IF(E27<=2,"Negative","Neutral")) -> Positive
A28: F0024 | B28: A0273 | C28: Assurance | D28: 46042 | E28: 4 | F28: The client portal made sharing documents simple. | G28: Responded | H28: digital | I28: =IF(E28>=4,"Positive",IF(E28<=2,"Negative","Neutral")) -> Positive
A29: F0025 | B29: A0226 | C29: Consulting | D29: 46171 | E29: 3 | F29: One point of contact made everything easier. | G29: Responded | H29: communication | I29: =IF(E29>=4,"Positive",IF(E29<=2,"Negative","Neutral")) -> Neutral
A30: F0026 | B30: A0129 | C30: Risk | D30: 46207 | E30: 2 | F30: Advice felt generic and not tailored to our industry. | G30: Open | H30: insight | I30: =IF(E30>=4,"Positive",IF(E30<=2,"Negative","Neutral")) -> Negative
A31: F0027 | B31: A0244 | C31: Consulting | D31: 46306 | E31: 4 | F31: The team brought genuinely useful sector insight. | G31: Closed | H31: insight | I31: =IF(E31>=4,"Positive",IF(E31<=2,"Negative","Neutral")) -> Positive
A32: F0028 | B32: A0061 | C32: Assurance | D32: 46309 | E32: 3 | F32: We were not told about changes to the timeline early enough. | G32: Open | H32: communication | I32: =IF(E32>=4,"Positive",IF(E32<=2,"Negative","Neutral")) -> Neutral
A33: F0029 | B33: A0162 | C33: Deals | D33: 46132 | E33: 4 | F33: Updates were clear and regular. | G33: Open | H33: communication | I33: =IF(E33>=4,"Positive",IF(E33<=2,"Negative","Neutral")) -> Positive
... A184: F0180 | B184: A0164 | C184: Consulting | D184: 46219 | E184: 5 | F184: Fees were fair for the quality delivered. | G184: Responded | H184: value | I184: =IF(E184>=4,"Positive",IF(E184<=2,"Negative","Neutral")) -> Positive

Sheet Events
A1: Event support: funnel by event (simulated)
A2: Invited to registered to attended to opportunities created.
A4: Event | B4: Industry | C4: Date | D4: Invited | E4: Registered | F4: Attended | G4: Opps created | H4: Registration rate | I4: Attendance rate | J4: Opps per 10 attendees
A5: Banking & Fintech Roundtable | B5: Financial Services | C5: 46226 | D5: 120 | E5: 64 | F5: 47 | G5: 6 | H5: =IF(D5=0,"",E5/D5) -> 0.53333333 | I5: =IF(E5=0,"",F5/E5) -> 0.734375 | J5: =IF(F5=0,"",G5/F5*10) -> 1.2765957
A6: Budget Breakfast: Tax Changes Briefing | B6: All industries | C6: 46240 | D6: 260 | E6: 148 | F6: 109 | G6: 11 | H6: =IF(D6=0,"",E6/D6) -> 0.56923077 | I6: =IF(E6=0,"",F6/E6) -> 0.73648649 | J6: =IF(F6=0,"",G6/F6*10) -> 1.0091743
A7: Energy Transition Forum | B7: Energy & Resources | C7: 46275 | D7: 90 | E7: 51 | F7: 38 | G7: 4 | H7: =IF(D7=0,"",E7/D7) -> 0.56666667 | I7: =IF(E7=0,"",F7/E7) -> 0.74509804 | J7: =IF(F7=0,"",G7/F7*10) -> 1.0526316
A8: Public Sector Finance Clinic | B8: Public Sector & Development | C8: 46289 | D8: 80 | E8: 42 | F8: 33 | G8: 3 | H8: =IF(D8=0,"",E8/D8) -> 0.525 | I8: =IF(E8=0,"",F8/E8) -> 0.78571429 | J8: =IF(F8=0,"",G8/F8*10) -> 0.90909091
A9: Health Leaders Dinner | B9: Health | C9: 46303 | D9: 40 | E9: 27 | F9: 22 | G9: 3 | H9: =IF(D9=0,"",E9/D9) -> 0.675 | I9: =IF(E9=0,"",F9/E9) -> 0.81481481 | J9: =IF(F9=0,"",G9/F9*10) -> 1.3636364
A10: Annual Industry Conference (planned) | B10: All industries | C10: 46345 | D10: 400 | E10: 0 | F10: 0 | G10: 0 | H10: =IF(D10=0,"",E10/D10) -> 0 | I10: =IF(E10=0,"",F10/E10) | J10: =IF(F10=0,"",G10/F10*10)
A11: Held events (excl. planned) | D11: =SUM(D5:D9) -> 590 | E11: =SUM(E5:E9) -> 332 | F11: =SUM(F5:F9) -> 249 | G11: =SUM(G5:G9) -> 27 | H11: =E11/D11 -> 0.56271186 | I11: =F11/E11 -> 0.75 | J11: =G11/F11*10 -> 1.0843373
A13: The last row is the planned annual conference: see comms/event_pack.md for the run-of-show, checklist and success measures.

Sheet Inputs
A1: Inputs
A2: Blue = input. All dashboards read these cells. Data is SIMULATED (see README).
A4: As-of date | B4: 46314
A5: Stale threshold (days without activity) | B5: 60
A6: FY27 start | B6: 46204
A7: FY27 end | B7: 46568
A8: Look-back for win rate (days) | B8: 365
A10: Stage | B10: Default probability %
A11: Prospecting | B11: 10
A12: Qualification | B12: 25
A13: Proposal | B13: 50
A14: Negotiation | B14: 75
A15: Closed Won | B15: 100
A16: Closed Lost | B16: 0
A19: Line of service | B19: FY27 BD target (KES m) [simulated]
A20: Assurance | B20: 1100
A21: Tax & Legal | B21: 1500
A22: Deals | B22: 900
A23: Consulting | B23: 1900
A24: Risk | B24: 600
A26: Targets are simulated planning inputs, not real firm targets.

Sheet Opps
A1: Opportunities: raw export plus live data-quality flags
A2: Columns A-N are the simulated Salesforce export. Columns O onward are formulas.
A4: Opp ID | B4: Account ID | C4: Opportunity | D4: Line of service | E4: Stage | F4: Amount (KES) | G4: Probability % | H4: Created | I4: Close date | J4: Last activity | K4: Owner ID | L4: Lead source | M4: Next step | N4: Lost reason | O4: Open? | P4: Industry | Q4: Tier | R4: Stage probability % | S4: Weighted (KES) | T4: Days since activity | U4: Flag: no amount | V4: Flag: no owner | W4: Flag: owner left | X4: Flag: close date passed | Y4: Flag: stale | Z4: Flag: probability off | AA4: Flag: no next step | AB4: Flag: lost no reason | AC4: Flags | AD4: Clean? | AE4: Closes in FY27 (open) | AF4: Won FY27 YTD | AG4: Closed in look-back | AH4: Cycle days
A5: O00001 | B5: A0002 | C5: Umoja Capital | Assurance | transformation | D5: Assurance | E5: Qualification | F5: 5676000 | G5: 25 | H5: 46199 | I5: 46522 | J5: 46293 | K5: U017 | L5: Cold outreach | M5: Await tender outcome | O5: =IF(OR(E5="Closed Won",E5="Closed Lost"),0,1) -> 1 | P5: =INDEX(Accounts!$K$5:$K$336,MATCH(B5,Accounts!$A$5:$A$336,0)) -> Financial Services | Q5: =INDEX(Accounts!$D$5:$D$336,MATCH(B5,Accounts!$A$5:$A$336,0)) -> Priority | R5: =INDEX(Inputs!$B$11:$B$16,MATCH(E5,Inputs!$A$11:$A$16,0)) -> 25 | S5: =IF(F5="",0,F5)*R5/100 -> 1419000 | T5: =Inputs!$B$4-J5 -> 21 | U5: =IF(OR(F5="",F5=0),1,0) -> 0 | V5: =IF(K5="",1,0) -> 0 | W5: =IF(AND(O5=1,K5<>"",COUNTIFS(Owners!$A$5:$A$32,K5,Owners!$E$5:$E$32,"No")>0),1,0) -> 0 | X5: =IF(AND(O5=1,I5<Inputs!$B$4),1,0) -> 0 | Y5: =IF(AND(O5=1,T5>Inputs!$B$5),1,0) -> 0 | Z5: =IF(AND(O5=1,G5<>R5),1,0) -> 0 | AA5: =IF(AND(O5=1,M5=""),1,0) -> 0 | AB5: =IF(AND(E5="Closed Lost",N5=""),1,0) -> 0 | AC5: =SUM(U5:AB5) -> 0 | AD5: =IF(AC5=0,1,0) -> 1 | AE5: =IF(AND(O5=1,I5>=Inputs!$B$6,I5<=Inputs!$B$7),1,0) -> 1 | AF5: =IF(AND(E5="Closed Won",I5>=Inputs!$B$6,I5<=Inputs!$B$4),1,0) -> 0 | AG5: =IF(AND(O5=0,I5>Inputs!$B$4-Inputs!$B$8,I5<=Inputs!$B$4),1,0) -> 0 | AH5: =I5-H5 -> 323
A6: O00002 | B6: A0102 | C6: Pwani Capital | Assurance | transformation | D6: Assurance | E6: Qualification | F6: 12441000 | G6: 25 | H6: 46179 | I6: 46557 | J6: 46298 | K6: U026 | L6: Digital | M6: Follow-up call | O6: =IF(OR(E6="Closed Won",E6="Closed Lost"),0,1) -> 1 | P6: =INDEX(Accounts!$K$5:$K$336,MATCH(B6,Accounts!$A$5:$A$336,0)) -> Financial Services | Q6: =INDEX(Accounts!$D$5:$D$336,MATCH(B6,Accounts!$A$5:$A$336,0)) -> Key | R6: =INDEX(Inputs!$B$11:$B$16,MATCH(E6,Inputs!$A$11:$A$16,0)) -> 25 | S6: =IF(F6="",0,F6)*R6/100 -> 3110250 | T6: =Inputs!$B$4-J6 -> 16 | U6: =IF(OR(F6="",F6=0),1,0) -> 0 | V6: =IF(K6="",1,0) -> 0 | W6: =IF(AND(O6=1,K6<>"",COUNTIFS(Owners!$A$5:$A$32,K6,Owners!$E$5:$E$32,"No")>0),1,0) -> 0 | X6: =IF(AND(O6=1,I6<Inputs!$B$4),1,0) -> 0 | Y6: =IF(AND(O6=1,T6>Inputs!$B$5),1,0) -> 0 | Z6: =IF(AND(O6=1,G6<>R6),1,0) -> 0 | AA6: =IF(AND(O6=1,M6=""),1,0) -> 0 | AB6: =IF(AND(E6="Closed Lost",N6=""),1,0) -> 0 | AC6: =SUM(U6:AB6) -> 0 | AD6: =IF(AC6=0,1,0) -> 1 | AE6: =IF(AND(O6=1,I6>=Inputs!$B$6,I6<=Inputs!$B$7),1,0) -> 1 | AF6: =IF(AND(E6="Closed Won",I6>=Inputs!$B$6,I6<=Inputs!$B$4),1,0) -> 0 | AG6: =IF(AND(O6=0,I6>Inputs!$B$4-Inputs!$B$8,I6<=Inputs!$B$4),1,0) -> 0 | AH6: =I6-H6 -> 378
A7: O00003 | B7: A0039 | C7: Baobab Power | Consulting | readiness | D7: Consulting | E7: Closed Lost | F7: 133434000 | G7: 0 | H7: 45949 | I7: 46048 | J7: 46048 | K7: U021 | L7: Event | N7: No decision | O7: =IF(OR(E7="Closed Won",E7="Closed Lost"),0,1) -> 0 | P7: =INDEX(Accounts!$K$5:$K$336,MATCH(B7,Accounts!$A$5:$A$336,0)) -> Energy & Resources | Q7: =INDEX(Accounts!$D$5:$D$336,MATCH(B7,Accounts!$A$5:$A$336,0)) -> Priority | R7: =INDEX(Inputs!$B$11:$B$16,MATCH(E7,Inputs!$A$11:$A$16,0)) -> 0 | S7: =IF(F7="",0,F7)*R7/100 -> 0 | T7: =Inputs!$B$4-J7 -> 266 | U7: =IF(OR(F7="",F7=0),1,0) -> 0 | V7: =IF(K7="",1,0) -> 0 | W7: =IF(AND(O7=1,K7<>"",COUNTIFS(Owners!$A$5:$A$32,K7,Owners!$E$5:$E$32,"No")>0),1,0) -> 0 | X7: =IF(AND(O7=1,I7<Inputs!$B$4),1,0) -> 0 | Y7: =IF(AND(O7=1,T7>Inputs!$B$5),1,0) -> 0 | Z7: =IF(AND(O7=1,G7<>R7),1,0) -> 0 | AA7: =IF(AND(O7=1,M7=""),1,0) -> 0 | AB7: =IF(AND(E7="Closed Lost",N7=""),1,0) -> 0 | AC7: =SUM(U7:AB7) -> 0 | AD7: =IF(AC7=0,1,0) -> 1 | AE7: =IF(AND(O7=1,I7>=Inputs!$B$6,I7<=Inputs!$B$7),1,0) -> 0 | AF7: =IF(AND(E7="Closed Won",I7>=Inputs!$B$6,I7<=Inputs!$B$4),1,0) -> 0 | AG7: =IF(AND(O7=0,I7>Inputs!$B$4-Inputs!$B$8,I7<=Inputs!$B$4),1,0) -> 1 | AH7: =I7-H7 -> 99
A8: O00004 | B8: A0152 | C8: Lakeview Sacco | Deals | transformation | D8: Deals | E8: Closed Won | F8: 18415000 | G8: 100 | H8: 45923 | I8: 46004 | J8: 46004 | K8: U024 | L8: Existing client | O8: =IF(OR(E8="Closed Won",E8="Closed Lost"),0,1) -> 0 | P8: =INDEX(Accounts!$K$5:$K$336,MATCH(B8,Accounts!$A$5:$A$336,0)) -> Financial Services | Q8: =INDEX(Accounts!$D$5:$D$336,MATCH(B8,Accounts!$A$5:$A$336,0)) -> Standard | R8: =INDEX(Inputs!$B$11:$B$16,MATCH(E8,Inputs!$A$11:$A$16,0)) -> 100 | S8: =IF(F8="",0,F8)*R8/100 -> 18415000 | T8: =Inputs!$B$4-J8 -> 310 | U8: =IF(OR(F8="",F8=0),1,0) -> 0 | V8: =IF(K8="",1,0) -> 0 | W8: =IF(AND(O8=1,K8<>"",COUNTIFS(Owners!$A$5:$A$32,K8,Owners!$E$5:$E$32,"No")>0),1,0) -> 0 | X8: =IF(AND(O8=1,I8<Inputs!$B$4),1,0) -> 0 | Y8: =IF(AND(O8=1,T8>Inputs!$B$5),1,0) -> 0 | Z8: =IF(AND(O8=1,G8<>R8),1,0) -> 0 | AA8: =IF(AND(O8=1,M8=""),1,0) -> 0 | AB8: =IF(AND(E8="Closed Lost",N8=""),1,0) -> 0 | AC8: =SUM(U8:AB8) -> 0 | AD8: =IF(AC8=0,1,0) -> 1 | AE8: =IF(AND(O8=1,I8>=Inputs!$B$6,I8<=Inputs!$B$7),1,0) -> 0 | AF8: =IF(AND(E8="Closed Won",I8>=Inputs!$B$6,I8<=Inputs!$B$4),1,0) -> 0 | AG8: =IF(AND(O8=0,I8>Inputs!$B$4-Inputs!$B$8,I8<=Inputs!$B$4),1,0) -> 1 | AH8: =I8-H8 -> 81
A9: O00005 | B9: A0137 | C9: Amani Networks | Tax & Legal | review | D9: Tax & Legal | E9: Qualification | F9: 17645000 | G9: 25 | H9: 46304 | I9: 46560 | J9: 46289 | K9: U025 | L9: Existing client | M9: Await tender outcome | O9: =IF(OR(E9="Closed Won",E9="Closed Lost"),0,1) -> 1 | P9: =INDEX(Accounts!$K$5:$K$336,MATCH(B9,Accounts!$A$5:$A$336,0)) -> Technology, Media & Telecom | Q9: =INDEX(Accounts!$D$5:$D$336,MATCH(B9,Accounts!$A$5:$A$336,0)) -> Standard | R9: =INDEX(Inputs!$B$11:$B$16,MATCH(E9,Inputs!$A$11:$A$16,0)) -> 25 | S9: =IF(F9="",0,F9)*R9/100 -> 4411250 | T9: =Inputs!$B$4-J9 -> 25 | U9: =IF(OR(F9="",F9=0),1,0) -> 0 | V9: =IF(K9="",1,0) -> 0 | W9: =IF(AND(O9=1,K9<>"",COUNTIFS(Owners!$A$5:$A$32,K9,Owners!$E$5:$E$32,"No")>0),1,0) -> 0 | X9: =IF(AND(O9=1,I9<Inputs!$B$4),1,0) -> 0 | Y9: =IF(AND(O9=1,T9>Inputs!$B$5),1,0) -> 0 | Z9: =IF(AND(O9=1,G9<>R9),1,0) -> 0 | AA9: =IF(AND(O9=1,M9=""),1,0) -> 0 | AB9: =IF(AND(E9="Closed Lost",N9=""),1,0) -> 0 | AC9: =SUM(U9:AB9) -> 0 | AD9: =IF(AC9=0,1,0) -> 1 | AE9: =IF(AND(O9=1,I9>=Inputs!$B$6,I9<=Inputs!$B$7),1,0) -> 1 | AF9: =IF(AND(E9="Closed Won",I9>=Inputs!$B$6,I9<=Inputs!$B$4),1,0) -> 0 | AG9: =IF(AND(O9=0,I9>Inputs!$B$4-Inputs!$B$8,I9<=Inputs!$B$4),1,0) -> 0 | AH9: =I9-H9 -> 256
A10: O00006 | B10: A0176 | C10: Baobab Capital | Deals | annual | D10: Deals | E10: Qualification | F10: 198924000 | G10: 25 | H10: 46281 | I10: 46533 | J10: 46290 | K10: U014 | L10: Thought leadership | M10: Partner meeting | O10: =IF(OR(E10="Closed Won",E10="Closed Lost"),0,1) -> 1 | P10: =INDEX(Accounts!$K$5:$K$336,MATCH(B10,Accounts!$A$5:$A$336,0)) -> Financial Services | Q10: =INDEX(Accounts!$D$5:$D$336,MATCH(B10,Accounts!$A$5:$A$336,0)) -> Standard | R10: =INDEX(Inputs!$B$11:$B$16,MATCH(E10,Inputs!$A$11:$A$16,0)) -> 25 | S10: =IF(F10="",0,F10)*R10/100 -> 49731000 | T10: =Inputs!$B$4-J10 -> 24 | U10: =IF(OR(F10="",F10=0),1,0) -> 0 | V10: =IF(K10="",1,0) -> 0 | W10: =IF(AND(O10=1,K10<>"",COUNTIFS(Owners!$A$5:$A$32,K10,Owners!$E$5:$E$32,"No")>0),1,0) -> 0 | X10: =IF(AND(O10=1,I10<Inputs!$B$4),1,0) -> 0 | Y10: =IF(AND(O10=1,T10>Inputs!$B$5),1,0) -> 0 | Z10: =IF(AND(O10=1,G10<>R10),1,0) -> 0 | AA10: =IF(AND(O10=1,M10=""),1,0) -> 0 | AB10: =IF(AND(E10="Closed Lost",N10=""),1,0) -> 0 | AC10: =SUM(U10:AB10) -> 0 | AD10: =IF(AC10=0,1,0) -> 1 | AE10: =IF(AND(O10=1,I10>=Inputs!$B$6,I10<=Inputs!$B$7),1,0) -> 1 | AF10: =IF(AND(E10="Closed Won",I10>=Inputs!$B$6,I10<=Inputs!$B$4),1,0) -> 0 | AG10: =IF(AND(O10=0,I10>Inputs!$B$4-Inputs!$B$8,I10<=Inputs!$B$4),1,0) -> 0 | AH10: =I10-H10 -> 252
A11: O00007 | B11: A0016 | C11: Mara Foods | Assurance | review | D11: Assurance | E11: Closed Lost | F11: 4008000 | G11: 0 | H11: 45896 | I11: 46156 | J11: 46156 | K11: U004 | L11: Event | N11: Price | O11: =IF(OR(E11="Closed Won",E11="Closed Lost"),0,1) -> 0 | P11: =INDEX(Accounts!$K$5:$K$336,MATCH(B11,Accounts!$A$5:$A$336,0)) -> Consumer & Retail | Q11: =INDEX(Accounts!$D$5:$D$336,MATCH(B11,Accounts!$A$5:$A$336,0)) -> Priority | R11: =INDEX(Inputs!$B$11:$B$16,MATCH(E11,Inputs!$A$11:$A$16,0)) -> 0 | S11: =IF(F11="",0,F11)*R11/100 -> 0 | T11: =Inputs!$B$4-J11 -> 158 | U11: =IF(OR(F11="",F11=0),1,0) -> 0 | V11: =IF(K11="",1,0) -> 0 | W11: =IF(AND(O11=1,K11<>"",COUNTIFS(Owners!$A$5:$A$32,K11,Owners!$E$5:$E$32,"No")>0),1,0) -> 0 | X11: =IF(AND(O11=1,I11<Inputs!$B$4),1,0) -> 0 | Y11: =IF(AND(O11=1,T11>Inputs!$B$5),1,0) -> 0 | Z11: =IF(AND(O11=1,G11<>R11),1,0) -> 0 | AA11: =IF(AND(O11=1,M11=""),1,0) -> 0 | AB11: =IF(AND(E11="Closed Lost",N11=""),1,0) -> 0 | AC11: =SUM(U11:AB11) -> 0 | AD11: =IF(AC11=0,1,0) -> 1 | AE11: =IF(AND(O11=1,I11>=Inputs!$B$6,I11<=Inputs!$B$7),1,0) -> 0 | AF11: =IF(AND(E11="Closed Won",I11>=Inputs!$B$6,I11<=Inputs!$B$4),1,0) -> 0 | AG11: =IF(AND(O11=0,I11>Inputs!$B$4-Inputs!$B$8,I11<=Inputs!$B$4),1,0) -> 1 | AH11: =I11-H11 -> 260
A12: O00008 | B12: A0149 | C12: Savanna Construction | Consulting | due diligence | D12: Consulting | E12: Qualification | F12: 25200000 | G12: 25 | H12: 46292 | I12: 46532 | J12: 46312 | K12: U019 | L12: Existing client | M12: Send proposal | O12: =IF(OR(E12="Closed Won",E12="Closed Lost"),0,1) -> 1 | P12: =INDEX(Accounts!$K$5:$K$336,MATCH(B12,Accounts!$A$5:$A$336,0)) -> Real Estate & Infrastructure | Q12: =INDEX(Accounts!$D$5:$D$336,MATCH(B12,Accounts!$A$5:$A$336,0)) -> Standard | R12: =INDEX(Inputs!$B$11:$B$16,MATCH(E12,Inputs!$A$11:$A$16,0)) -> 25 | S12: =IF(F12="",0,F12)*R12/100 -> 6300000 | T12: =Inputs!$B$4-J12 -> 2 | U12: =IF(OR(F12="",F12=0),1,0) -> 0 | V12: =IF(K12="",1,0) -> 0 | W12: =IF(AND(O12=1,K12<>"",COUNTIFS(Owners!$A$5:$A$32,K12,Owners!$E$5:$E$32,"No")>0),1,0) -> 0 | X12: =IF(AND(O12=1,I12<Inputs!$B$4),1,0) -> 0 | Y12: =IF(AND(O12=1,T12>Inputs!$B$5),1,0) -> 0 | Z12: =IF(AND(O12=1,G12<>R12),1,0) -> 0 | AA12: =IF(AND(O12=1,M12=""),1,0) -> 0 | AB12: =IF(AND(E12="Closed Lost",N12=""),1,0) -> 0 | AC12: =SUM(U12:AB12) -> 0 | AD12: =IF(AC12=0,1,0) -> 1 | AE12: =IF(AND(O12=1,I12>=Inputs!$B$6,I12<=Inputs!$B$7),1,0) -> 1 | AF12: =IF(AND(E12="Closed Won",I12>=Inputs!$B$6,I12<=Inputs!$B$4),1,0) -> 0 | AG12: =IF(AND(O12=0,I12>Inputs!$B$4-Inputs!$B$8,I12<=Inputs!$B$4),1,0) -> 0 | AH12: =I12-H12 -> 240
A13: O00009 | B13: A0051 | C13: Kibo Sacco | Consulting | readiness | D13: Consulting | E13: Closed Lost | F13: 2821000 | G13: 0 | H13: 45932 | I13: 46223 | J13: 46223 | K13: U006 | L13: Existing client | N13: Price | O13: =IF(OR(E13="Closed Won",E13="Closed Lost"),0,1) -> 0 | P13: =INDEX(Accounts!$K$5:$K$336,MATCH(B13,Accounts!$A$5:$A$336,0)) -> Financial Services | Q13: =INDEX(Accounts!$D$5:$D$336,MATCH(B13,Accounts!$A$5:$A$336,0)) -> Key | R13: =INDEX(Inputs!$B$11:$B$16,MATCH(E13,Inputs!$A$11:$A$16,0)) -> 0 | S13: =IF(F13="",0,F13)*R13/100 -> 0 | T13: =Inputs!$B$4-J13 -> 91 | U13: =IF(OR(F13="",F13=0),1,0) -> 0 | V13: =IF(K13="",1,0) -> 0 | W13: =IF(AND(O13=1,K13<>"",COUNTIFS(Owners!$A$5:$A$32,K13,Owners!$E$5:$E$32,"No")>0),1,0) -> 0 | X13: =IF(AND(O13=1,I13<Inputs!$B$4),1,0) -> 0 | Y13: =IF(AND(O13=1,T13>Inputs!$B$5),1,0) -> 0 | Z13: =IF(AND(O13=1,G13<>R13),1,0) -> 0 | AA13: =IF(AND(O13=1,M13=""),1,0) -> 0 | AB13: =IF(AND(E13="Closed Lost",N13=""),1,0) -> 0 | AC13: =SUM(U13:AB13) -> 0 | AD13: =IF(AC13=0,1,0) -> 1 | AE13: =IF(AND(O13=1,I13>=Inputs!$B$6,I13<=Inputs!$B$7),1,0) -> 0 | AF13: =IF(AND(E13="Closed Won",I13>=Inputs!$B$6,I13<=Inputs!$B$4),1,0) -> 0 | AG13: =IF(AND(O13=0,I13>Inputs!$B$4-Inputs!$B$8,I13<=Inputs!$B$4),1,0) -> 1 | AH13: =I13-H13 -> 291
A14: O00010 | B14: A0032 | C14: Jambo Tea Estates | Risk | advisory | D14: Risk | E14: Qualification | F14: 6036000 | G14: 100 | H14: 46263 | I14: 46557 | J14: 46208 | K14: U004 | L14: Cold outreach | M14: Partner meeting | O14: =IF(OR(E14="Closed Won",E14="Closed Lost"),0,1) -> 1 | P14: =INDEX(Accounts!$K$5:$K$336,MATCH(B14,Accounts!$A$5:$A$336,0)) -> Agribusiness | Q14: =INDEX(Accounts!$D$5:$D$336,MATCH(B14,Accounts!$A$5:$A$336,0)) -> Priority | R14: =INDEX(Inputs!$B$11:$B$16,MATCH(E14,Inputs!$A$11:$A$16,0)) -> 25 | S14: =IF(F14="",0,F14)*R14/100 -> 1509000 | T14: =Inputs!$B$4-J14 -> 106 | U14: =IF(OR(F14="",F14=0),1,0) -> 0 | V14: =IF(K14="",1,0) -> 0 | W14: =IF(AND(O14=1,K14<>"",COUNTIFS(Owners!$A$5:$A$32,K14,Owners!$E$5:$E$32,"No")>0),1,0) -> 0 | X14: =IF(AND(O14=1,I14<Inputs!$B$4),1,0) -> 0 | Y14: =IF(AND(O14=1,T14>Inputs!$B$5),1,0) -> 1 | Z14: =IF(AND(O14=1,G14<>R14),1,0) -> 1 | AA14: =IF(AND(O14=1,M14=""),1,0) -> 0 | AB14: =IF(AND(E14="Closed Lost",N14=""),1,0) -> 0 | AC14: =SUM(U14:AB14) -> 2 | AD14: =IF(AC14=0,1,0) -> 0 | AE14: =IF(AND(O14=1,I14>=Inputs!$B$6,I14<=Inputs!$B$7),1,0) -> 1 | AF14: =IF(AND(E14="Closed Won",I14>=Inputs!$B$6,I14<=Inputs!$B$4),1,0) -> 0 | AG14: =IF(AND(O14=0,I14>Inputs!$B$4-Inputs!$B$8,I14<=Inputs!$B$4),1,0) -> 0 | AH14: =I14-H14 -> 294
A15: O00011 | B15: A0199 | C15: Amani Commission | Tax & Legal | due diligence | D15: Tax & Legal | E15: Closed Lost | F15: 4076000 | G15: 0 | H15: 46058 | I15: 46134 | J15: 46134 | K15: U006 | L15: Referral | N15: Incumbent retained | O15: =IF(OR(E15="Closed Won",E15="Closed Lost"),0,1) -> 0 | P15: =INDEX(Accounts!$K$5:$K$336,MATCH(B15,Accounts!$A$5:$A$336,0)) -> Public Sector & Development | Q15: =INDEX(Accounts!$D$5:$D$336,MATCH(B15,Accounts!$A$5:$A$336,0)) -> Standard | R15: =INDEX(Inputs!$B$11:$B$16,MATCH(E15,Inputs!$A$11:$A$16,0)) -> 0 | S15: =IF(F15="",0,F15)*R15/100 -> 0 | T15: =Inputs!$B$4-J15 -> 180 | U15: =IF(OR(F15="",F15=0),1,0) -> 0 | V15: =IF(K15="",1,0) -> 0 | W15: =IF(AND(O15=1,K15<>"",COUNTIFS(Owners!$A$5:$A$32,K15,Owners!$E$5:$E$32,"No")>0),1,0) -> 0 | X15: =IF(AND(O15=1,I15<Inputs!$B$4),1,0) -> 0 | Y15: =IF(AND(O15=1,T15>Inputs!$B$5),1,0) -> 0 | Z15: =IF(AND(O15=1,G15<>R15),1,0) -> 0 | AA15: =IF(AND(O15=1,M15=""),1,0) -> 0 | AB15: =IF(AND(E15="Closed Lost",N15=""),1,0) -> 0 | AC15: =SUM(U15:AB15) -> 0 | AD15: =IF(AC15=0,1,0) -> 1 | AE15: =IF(AND(O15=1,I15>=Inputs!$B$6,I15<=Inputs!$B$7),1,0) -> 0 | AF15: =IF(AND(E15="Closed Won",I15>=Inputs!$B$6,I15<=Inputs!$B$4),1,0) -> 0 | AG15: =IF(AND(O15=0,I15>Inputs!$B$4-Inputs!$B$8,I15<=Inputs!$B$4),1,0) -> 1 | AH15: =I15-H15 -> 76
A16: O00012 | B16: A0027 | C16: Safari Growers | Tax & Legal | compliance | D16: Tax & Legal | E16: Proposal | F16: 2608000 | G16: 50 | H16: 46223 | I16: 46370 | J16: 46281 | K16: U006 | L16: Referral | M16: Scope workshop | O16: =IF(OR(E16="Closed Won",E16="Closed Lost"),0,1) -> 1 | P16: =INDEX(Accounts!$K$5:$K$336,MATCH(B16,Accounts!$A$5:$A$336,0)) -> Agribusiness | Q16: =INDEX(Accounts!$D$5:$D$336,MATCH(B16,Accounts!$A$5:$A$336,0)) -> Priority | R16: =INDEX(Inputs!$B$11:$B$16,MATCH(E16,Inputs!$A$11:$A$16,0)) -> 50 | S16: =IF(F16="",0,F16)*R16/100 -> 1304000 | T16: =Inputs!$B$4-J16 -> 33 | U16: =IF(OR(F16="",F16=0),1,0) -> 0 | V16: =IF(K16="",1,0) -> 0 | W16: =IF(AND(O16=1,K16<>"",COUNTIFS(Owners!$A$5:$A$32,K16,Owners!$E$5:$E$32,"No")>0),1,0) -> 0 | X16: =IF(AND(O16=1,I16<Inputs!$B$4),1,0) -> 0 | Y16: =IF(AND(O16=1,T16>Inputs!$B$5),1,0) -> 0 | Z16: =IF(AND(O16=1,G16<>R16),1,0) -> 0 | AA16: =IF(AND(O16=1,M16=""),1,0) -> 0 | AB16: =IF(AND(E16="Closed Lost",N16=""),1,0) -> 0 | AC16: =SUM(U16:AB16) -> 0 | AD16: =IF(AC16=0,1,0) -> 1 | AE16: =IF(AND(O16=1,I16>=Inputs!$B$6,I16<=Inputs!$B$7),1,0) -> 1 | AF16: =IF(AND(E16="Closed Won",I16>=Inputs!$B$6,I16<=Inputs!$B$4),1,0) -> 0 | AG16: =IF(AND(O16=0,I16>Inputs!$B$4-Inputs!$B$8,I16<=Inputs!$B$4),1,0) -> 0 | AH16: =I16-H16 -> 147
